<?xml version="1.0" ?>
<robot name="create3_urdf_assem" xmlns:xacro="http://www.ros.org/wiki/xacro">

<xacro:include filename="$(find create3_urdf_assem_description)/urdf/materials.xacro" />
<xacro:include filename="$(find create3_urdf_assem_description)/urdf/create3_urdf_assem.trans" />
<link name="base_link">
  <inertial>
    <origin xyz="-0.0477402134251398 0.000298374555205472 0.0707742269562776" rpy="0 0 0"/>
    <mass value="34201.1491114537"/>
    <inertia ixx="38.6220921391776" iyy="134.567850741024" izz="159.561066653326" ixy="16.1194005724848" iyz="2.58291353301587" ixz="-4.23925375117913"/>
  </inertial>
  <visual>
    <origin xyz="0 0 0" rpy="0 0 0"/>
    <geometry>
      <mesh filename="package://create3_urdf_assem_description/meshes/base_link.stl" scale="0.001 0.001 0.001"/>
    </geometry>
    <material name="steel_satin"/>
  </visual>
  <collision>
    <origin xyz="0 0 0" rpy="0 0 0"/>
    <geometry>
      <mesh filename="package://create3_urdf_assem_description/meshes/base_link.stl" scale="0.001 0.001 0.001"/>
    </geometry>
  </collision>
</link>

<link name="Support_large_v1_1">
  <inertial>
    <origin xyz="-0.004383915570773139 0.014999999999986325 0.009761679303239137" rpy="0 0 0"/>
    <mass value="0.0349174875193363"/>
    <inertia ixx="2.26200324476449e-05" iyy="5.29701481160987e-06" izz="1.97076884200252e-05" ixy="-3.787468963604769e-20" iyz="-4.178571342686151e-18" ixz="1.03876508360679e-09"/>
  </inertial>
  <visual>
    <origin xyz="-0.107763 0.015 -0.0936" rpy="0 0 0"/>
    <geometry>
      <mesh filename="package://create3_urdf_assem_description/meshes/Support_large_v1_1.stl" scale="0.001 0.001 0.001"/>
    </geometry>
    <material name="aluminum_polished"/>
  </visual>
  <collision>
    <origin xyz="-0.107763 0.015 -0.0936" rpy="0 0 0"/>
    <geometry>
      <mesh filename="package://create3_urdf_assem_description/meshes/Support_large_v1_1.stl" scale="0.001 0.001 0.001"/>
    </geometry>
  </collision>
</link>

<link name="RDS3225_-_for_URDF_v2_1">
  <inertial>
    <origin xyz="-5.659439965971513e-07 0.025698274532342767 0.012102967232937745" rpy="0 0 0"/>
    <mass value="0.293701869916715"/>
    <inertia ixx="9.81025644835876e-05" iyy="5.67051291990688e-05" izz="6.03806117120461e-05" ixy="1.06173111667378e-10" iyz="1.51865306677981e-07" ixz="-1.84285327449463e-10"/>
  </inertial>
  <visual>
    <origin xyz="-0.103376 0.0265 -0.1205" rpy="0 0 0"/>
    <geometry>
      <mesh filename="package://create3_urdf_assem_description/meshes/RDS3225_-_for_URDF_v2_1.stl" scale="0.001 0.001 0.001"/>
    </geometry>
    <material name="aluminum_anodized_glossy_grey"/>
  </visual>
  <collision>
    <origin xyz="-0.103376 0.0265 -0.1205" rpy="0 0 0"/>
    <geometry>
      <mesh filename="package://create3_urdf_assem_description/meshes/RDS3225_-_for_URDF_v2_1.stl" scale="0.001 0.001 0.001"/>
    </geometry>
  </collision>
</link>

<link name="ArmLink_v2_1">
  <inertial>
    <origin xyz="-0.0018531703965943142 0.0003540965645935584 0.032021608880066554" rpy="0 0 0"/>
    <mass value="0.0389779069771219"/>
    <inertia ixx="2.99541900814009e-05" iyy="2.38388727478328e-05" izz="1.22745171835179e-05" ixy="-8.71277974867326e-10" iyz="-2.26928593669882e-07" ixz="-4.22491135078275e-09"/>
  </inertial>
  <visual>
    <origin xyz="-0.103376 0.00075 -0.158426" rpy="0 0 0"/>
    <geometry>
      <mesh filename="package://create3_urdf_assem_description/meshes/ArmLink_v2_1.stl" scale="0.001 0.001 0.001"/>
    </geometry>
    <material name="nylon_12_with_formlabs_fuse_1_3d_printer"/>
  </visual>
  <collision>
    <origin xyz="-0.103376 0.00075 -0.158426" rpy="0 0 0"/>
    <geometry>
      <mesh filename="package://create3_urdf_assem_description/meshes/ArmLink_v2_1.stl" scale="0.001 0.001 0.001"/>
    </geometry>
  </collision>
</link>

<link name="Support_large_v1_2">
  <inertial>
    <origin xyz="3.084429226987706e-06 -1.356261023627292e-14 0.009761205723497146" rpy="0 0 0"/>
    <mass value="0.0349174875193363"/>
    <inertia ixx="2.26200324476449e-05" iyy="5.2970148116103e-06" izz="1.97076884200251e-05" ixy="6.704795173109821e-20" iyz="-4.175872429963701e-18" ixz="1.03876508360679e-09"/>
  </inertial>
  <visual>
    <origin xyz="-0.103376 5e-05 -0.221926" rpy="0 0 0"/>
    <geometry>
      <mesh filename="package://create3_urdf_assem_description/meshes/Support_large_v1_2.stl" scale="0.001 0.001 0.001"/>
    </geometry>
    <material name="aluminum_polished"/>
  </visual>
  <collision>
    <origin xyz="-0.103376 5e-05 -0.221926" rpy="0 0 0"/>
    <geometry>
      <mesh filename="package://create3_urdf_assem_description/meshes/Support_large_v1_2.stl" scale="0.001 0.001 0.001"/>
    </geometry>
  </collision>
</link>

<link name="RDS3225_-_for_URDF_v2_2">
  <inertial>
    <origin xyz="-5.659439962779622e-07 0.025698274532342868 0.012102493653195767" rpy="0 0 0"/>
    <mass value="0.293701869916715"/>
    <inertia ixx="9.81025644835841e-05" iyy="5.67051291990688e-05" izz="6.03806117120461e-05" ixy="1.06173111589451e-10" iyz="1.51865306677974e-07" ixz="-1.84285326582101e-10"/>
  </inertial>
  <visual>
    <origin xyz="-0.103376 0.02655 -0.248826" rpy="0 0 0"/>
    <geometry>
      <mesh filename="package://create3_urdf_assem_description/meshes/RDS3225_-_for_URDF_v2_2.stl" scale="0.001 0.001 0.001"/>
    </geometry>
    <material name="aluminum_anodized_glossy_grey"/>
  </visual>
  <collision>
    <origin xyz="-0.103376 0.02655 -0.248826" rpy="0 0 0"/>
    <geometry>
      <mesh filename="package://create3_urdf_assem_description/meshes/RDS3225_-_for_URDF_v2_2.stl" scale="0.001 0.001 0.001"/>
    </geometry>
  </collision>
</link>

<link name="ArmLink_v2_2">
  <inertial>
    <origin xyz="-0.0018531703965940366 0.00035409656459368645 0.032022135300324495" rpy="0 0 0"/>
    <mass value="0.0389779069771219"/>
    <inertia ixx="2.99541900814016e-05" iyy="2.38388727478315e-05" izz="1.22745171835179e-05" ixy="-8.71277975441614e-10" iyz="-2.26928593670256e-07" ixz="-4.22491135067433e-09"/>
  </inertial>
  <visual>
    <origin xyz="-0.103376 0.0008 -0.286751" rpy="0 0 0"/>
    <geometry>
      <mesh filename="package://create3_urdf_assem_description/meshes/ArmLink_v2_2.stl" scale="0.001 0.001 0.001"/>
    </geometry>
    <material name="nylon_12_with_formlabs_fuse_1_3d_printer"/>
  </visual>
  <collision>
    <origin xyz="-0.103376 0.0008 -0.286751" rpy="0 0 0"/>
    <geometry>
      <mesh filename="package://create3_urdf_assem_description/meshes/ArmLink_v2_2.stl" scale="0.001 0.001 0.001"/>
    </geometry>
  </collision>
</link>

<link name="Support_large_v1_3">
  <inertial>
    <origin xyz="3.0844292272236284e-06 -1.3419875020265204e-14 0.00976173214375503" rpy="0 0 0"/>
    <mass value="0.0349174875193363"/>
    <inertia ixx="2.26200324476454e-05" iyy="5.29701481161073e-06" izz="1.97076884200251e-05" ixy="5.712178438046188e-20" iyz="-4.170578474043361e-18" ixz="1.03876508349837e-09"/>
  </inertial>
  <visual>
    <origin xyz="-0.103376 0.0001 -0.350251" rpy="0 0 0"/>
    <geometry>
      <mesh filename="package://create3_urdf_assem_description/meshes/Support_large_v1_3.stl" scale="0.001 0.001 0.001"/>
    </geometry>
    <material name="aluminum_polished"/>
  </visual>
  <collision>
    <origin xyz="-0.103376 0.0001 -0.350251" rpy="0 0 0"/>
    <geometry>
      <mesh filename="package://create3_urdf_assem_description/meshes/Support_large_v1_3.stl" scale="0.001 0.001 0.001"/>
    </geometry>
  </collision>
</link>

<link name="RDS3225_-_for_URDF_v2_3">
  <inertial>
    <origin xyz="-5.659439959865287e-07 0.02569827453234305 0.012103020073453818" rpy="0 0 0"/>
    <mass value="0.293701869916715"/>
    <inertia ixx="9.81025644835806e-05" iyy="5.67051291990722e-05" izz="6.03806117120461e-05" ixy="1.06173111663989e-10" iyz="1.51865306677988e-07" ixz="-1.84285326582101e-10"/>
  </inertial>
  <visual>
    <origin xyz="-0.103376 0.0266 -0.377151" rpy="0 0 0"/>
    <geometry>
      <mesh filename="package://create3_urdf_assem_description/meshes/RDS3225_-_for_URDF_v2_3.stl" scale="0.001 0.001 0.001"/>
    </geometry>
    <material name="aluminum_anodized_glossy_grey"/>
  </visual>
  <collision>
    <origin xyz="-0.103376 0.0266 -0.377151" rpy="0 0 0"/>
    <geometry>
      <mesh filename="package://create3_urdf_assem_description/meshes/RDS3225_-_for_URDF_v2_3.stl" scale="0.001 0.001 0.001"/>
    </geometry>
  </collision>
</link>

<link name="Base_v3_1">
  <inertial>
    <origin xyz="-8.36645972755179e-05 0.002452514318840418 0.020098428040290883" rpy="0 0 0"/>
    <mass value="0.658770656127906"/>
    <inertia ixx="0.000244632378241766" iyy="0.000250469936897479" izz="0.000333289784067105" ixy="1.16808881628214e-06" iyz="6.89073833154657e-07" ixz="-1.40313941103878e-05"/>
  </inertial>
  <visual>
    <origin xyz="-0.103376 0.00085 -0.415077" rpy="0 0 0"/>
    <geometry>
      <mesh filename="package://create3_urdf_assem_description/meshes/Base_v3_1.stl" scale="0.001 0.001 0.001"/>
    </geometry>
    <material name="steel_satin"/>
  </visual>
  <collision>
    <origin xyz="-0.103376 0.00085 -0.415077" rpy="0 0 0"/>
    <geometry>
      <mesh filename="package://create3_urdf_assem_description/meshes/Base_v3_1.stl" scale="0.001 0.001 0.001"/>
    </geometry>
  </collision>
</link>

<link name="DriverArm_v1_1">
  <inertial>
    <origin xyz="0.0018284748210474489 1.339846118412688e-06 0.02058562434802802" rpy="0 0 0"/>
    <mass value="0.0260050919796781"/>
    <inertia ixx="1.08216757759147e-05" iyy="1.12675016782767e-05" izz="1.39002131213238e-06" ixy="-2.617612026521157e-11" iyz="-7.67259041050588e-10" ixz="-2.12902308169022e-07"/>
  </inertial>
  <visual>
    <origin xyz="-0.129683 -0.01155 -0.438077" rpy="0 0 0"/>
    <geometry>
      <mesh filename="package://create3_urdf_assem_description/meshes/DriverArm_v1_1.stl" scale="0.001 0.001 0.001"/>
    </geometry>
    <material name="steel_satin"/>
  </visual>
  <collision>
    <origin xyz="-0.129683 -0.01155 -0.438077" rpy="0 0 0"/>
    <geometry>
      <mesh filename="package://create3_urdf_assem_description/meshes/DriverArm_v1_1.stl" scale="0.001 0.001 0.001"/>
    </geometry>
  </collision>
</link>

<link name="DrivenArm_v1_1">
  <inertial>
    <origin xyz="0.001867586153700418 -1.028091941440712e-09 0.021529285671453402" rpy="0 0 0"/>
    <mass value="0.0248303870156428"/>
    <inertia ixx="1.02836200396037e-05" iyy="1.07659428495331e-05" izz="1.33855773777597e-06" ixy="-2.352908449673730e-15" iyz="4.551363626259519e-13" ixz="-1.92178432330747e-07"/>
  </inertial>
  <visual>
    <origin xyz="-0.129294 0.01285 -0.438127" rpy="0 0 0"/>
    <geometry>
      <mesh filename="package://create3_urdf_assem_description/meshes/DrivenArm_v1_1.stl" scale="0.001 0.001 0.001"/>
    </geometry>
    <material name="steel_satin"/>
  </visual>
  <collision>
    <origin xyz="-0.129294 0.01285 -0.438127" rpy="0 0 0"/>
    <geometry>
      <mesh filename="package://create3_urdf_assem_description/meshes/DrivenArm_v1_1.stl" scale="0.001 0.001 0.001"/>
    </geometry>
  </collision>
</link>

<link name="FrontArmLeft_v1_1">
  <inertial>
    <origin xyz="0.002212929708058642 -3.8028149261602057e-07 0.03526460296004863" rpy="0 0 0"/>
    <mass value="0.0128022837025148"/>
    <inertia ixx="2.34657891009073e-06" iyy="3.20907808778678e-06" izz="9.34034314273822e-07" ixy="-4.626683369716588e-12" iyz="-9.603896897311583e-11" ixz="-6.68140775857877e-08"/>
  </inertial>
  <visual>
    <origin xyz="-0.129294 0.005196 -0.457429" rpy="0 0 0"/>
    <geometry>
      <mesh filename="package://create3_urdf_assem_description/meshes/FrontArmLeft_v1_1.stl" scale="0.001 0.001 0.001"/>
    </geometry>
    <material name="steel_satin"/>
  </visual>
  <collision>
    <origin xyz="-0.129294 0.005196 -0.457429" rpy="0 0 0"/>
    <geometry>
      <mesh filename="package://create3_urdf_assem_description/meshes/FrontArmLeft_v1_1.stl" scale="0.001 0.001 0.001"/>
    </geometry>
  </collision>
</link>

<link name="FrontArmRight_v1_1">
  <inertial>
    <origin xyz="0.002212929708103717 5.340535295713517e-07 0.03526460296002465" rpy="0 0 0"/>
    <mass value="0.0128022837024801"/>
    <inertia ixx="2.34657899732173e-06" iyy="3.20907808777334e-06" izz="9.3403440149889e-07" ixy="4.792456000629445e-12" iyz="9.563218541852126e-11" ixz="-6.68140775868719e-08"/>
  </inertial>
  <visual>
    <origin xyz="-0.129294 -0.0039 -0.457429" rpy="0 0 0"/>
    <geometry>
      <mesh filename="package://create3_urdf_assem_description/meshes/FrontArmRight_v1_1.stl" scale="0.001 0.001 0.001"/>
    </geometry>
    <material name="steel_satin"/>
  </visual>
  <collision>
    <origin xyz="-0.129294 -0.0039 -0.457429" rpy="0 0 0"/>
    <geometry>
      <mesh filename="package://create3_urdf_assem_description/meshes/FrontArmRight_v1_1.stl" scale="0.001 0.001 0.001"/>
    </geometry>
  </collision>
</link>

<link name="LeftPad_v1_1">
  <inertial>
    <origin xyz="-0.015999952624356995 -0.005420795704652397 0.00898870884090086" rpy="0 0 0"/>
    <mass value="0.0447667884009862"/>
    <inertia ixx="1.11099961075251e-05" iyy="1.57590900927047e-05" izz="7.60209937602336e-06" ixy="3.043686098514256e-12" iyz="-2.25789445711244e-06" ixz="-1.347813353980154e-11"/>
  </inertial>
  <visual>
    <origin xyz="-0.146794 0.005196 -0.500014" rpy="0 0 0"/>
    <geometry>
      <mesh filename="package://create3_urdf_assem_description/meshes/LeftPad_v1_1.stl" scale="0.001 0.001 0.001"/>
    </geometry>
    <material name="steel_satin"/>
  </visual>
  <collision>
    <origin xyz="-0.146794 0.005196 -0.500014" rpy="0 0 0"/>
    <geometry>
      <mesh filename="package://create3_urdf_assem_description/meshes/LeftPad_v1_1.stl" scale="0.001 0.001 0.001"/>
    </geometry>
  </collision>
</link>

<link name="RightPad_v1_1">
  <inertial>
    <origin xyz="-0.015999968476965165 0.005420948882587669 0.008988708845328097" rpy="0 0 0"/>
    <mass value="0.0447667871612714"/>
    <inertia ixx="1.11099970953737e-05" iyy="1.57590896759773e-05" izz="7.60210037507717e-06" ixy="-1.892359688816358e-12" iyz="2.25789089323711e-06" ixz="-1.551214452027994e-11"/>
  </inertial>
  <visual>
    <origin xyz="-0.146794 -0.0039 -0.500014" rpy="0 0 0"/>
    <geometry>
      <mesh filename="package://create3_urdf_assem_description/meshes/RightPad_v1_1.stl" scale="0.001 0.001 0.001"/>
    </geometry>
    <material name="steel_satin"/>
  </visual>
  <collision>
    <origin xyz="-0.146794 -0.0039 -0.500014" rpy="0 0 0"/>
    <geometry>
      <mesh filename="package://create3_urdf_assem_description/meshes/RightPad_v1_1.stl" scale="0.001 0.001 0.001"/>
    </geometry>
  </collision>
</link>

<joint name="Rigid 31" type="fixed">
  <origin xyz="0.107763 -0.015 0.0936" rpy="0 0 0"/>
  <parent link="base_link"/>
  <child link="Support_large_v1_1"/>
</joint>

<joint name="Revolute 32" type="revolute">
  <origin xyz="-0.004387 -0.0115 0.0269" rpy="0 0 0"/>
  <parent link="Support_large_v1_1"/>
  <child link="RDS3225_-_for_URDF_v2_1"/>
  <axis xyz="-0.0 -1.0 -0.0"/>
  <limit upper="2.094395" lower="-2.094395" effort="100" velocity="100"/>
</joint>

<joint name="Rigid 33" type="fixed">
  <origin xyz="0.0 0.02575 0.037926" rpy="0 0 0"/>
  <parent link="RDS3225_-_for_URDF_v2_1"/>
  <child link="ArmLink_v2_1"/>
</joint>

<joint name="Rigid 34" type="fixed">
  <origin xyz="0.0 0.0007 0.0635" rpy="0 0 0"/>
  <parent link="ArmLink_v2_1"/>
  <child link="Support_large_v1_2"/>
</joint>

<joint name="Revolute 35" type="revolute">
  <origin xyz="0.0 -0.0265 0.0269" rpy="0 0 0"/>
  <parent link="Support_large_v1_2"/>
  <child link="RDS3225_-_for_URDF_v2_2"/>
  <axis xyz="0.0 -1.0 0.0"/>
  <limit upper="2.094395" lower="-2.094395" effort="100" velocity="100"/>
</joint>

<joint name="Rigid 36" type="fixed">
  <origin xyz="0.0 0.02575 0.037925" rpy="0 0 0"/>
  <parent link="RDS3225_-_for_URDF_v2_2"/>
  <child link="ArmLink_v2_2"/>
</joint>

<joint name="Rigid 37" type="fixed">
  <origin xyz="0.0 0.0007 0.0635" rpy="0 0 0"/>
  <parent link="ArmLink_v2_2"/>
  <child link="Support_large_v1_3"/>
</joint>

<joint name="Revolute 38" type="revolute">
  <origin xyz="0.0 -0.0265 0.0269" rpy="0 0 0"/>
  <parent link="Support_large_v1_3"/>
  <child link="RDS3225_-_for_URDF_v2_3"/>
  <axis xyz="0.0 -1.0 0.0"/>
  <limit upper="2.094395" lower="-2.094395" effort="100" velocity="100"/>
</joint>

<joint name="Rigid 59" type="fixed">
  <origin xyz="0.0 0.02575 0.037926" rpy="0 0 0"/>
  <parent link="RDS3225_-_for_URDF_v2_3"/>
  <child link="Base_v3_1"/>
</joint>

<joint name="Revolute 60" type="continuous">
  <origin xyz="0.026307 0.0124 0.023" rpy="0 0 0"/>
  <parent link="Base_v3_1"/>
  <child link="DriverArm_v1_1"/>
  <axis xyz="1.0 -1e-06 -1e-06"/>
</joint>

<joint name="Revolute 61" type="continuous">
  <origin xyz="0.025918 -0.012 0.02305" rpy="0 0 0"/>
  <parent link="Base_v3_1"/>
  <child link="DrivenArm_v1_1"/>
  <axis xyz="-1.0 -0.0 1e-06"/>
</joint>

<joint name="Revolute 62" type="continuous">
  <origin xyz="0.025918 -0.004346 0.042352" rpy="0 0 0"/>
  <parent link="Base_v3_1"/>
  <child link="FrontArmLeft_v1_1"/>
  <axis xyz="-1.0 -0.0 1e-06"/>
</joint>

<joint name="Revolute 63" type="continuous">
  <origin xyz="0.025918 0.00475 0.042352" rpy="0 0 0"/>
  <parent link="Base_v3_1"/>
  <child link="FrontArmRight_v1_1"/>
  <axis xyz="-1.0 -0.0 1e-06"/>
</joint>

<joint name="Revolute 64" type="continuous">
  <origin xyz="0.0175 0.0 0.042585" rpy="0 0 0"/>
  <parent link="FrontArmLeft_v1_1"/>
  <child link="LeftPad_v1_1"/>
  <axis xyz="-1.0 -0.0 0.0"/>
</joint>

<joint name="Revolute 65" type="continuous">
  <origin xyz="0.0175 0.0 0.042585" rpy="0 0 0"/>
  <parent link="FrontArmRight_v1_1"/>
  <child link="RightPad_v1_1"/>
  <axis xyz="-1.0 -0.0 0.0"/>
</joint>

</robot>
